<sdf version="1.7">
  <world name="coworking">
    <physics name="10ms" type="ode">
      <max_step_size>0.01</max_step_size>
      <real_time_factor>1.0</real_time_factor>
    </physics>
    <plugin filename="libgz-sim-physics-system.so" name="gz::sim::systems::Physics">
    </plugin>
    <plugin filename="libgz-sim-user-commands-system.so" name="gz::sim::systems::UserCommands">
    </plugin>
    <plugin filename="libgz-sim-scene-broadcaster-system.so" name="gz::sim::systems::SceneBroadcaster">
    </plugin>
    <plugin filename="libdoor.so" name="door">
    </plugin>
    <plugin filename="liblift.so" name="lift">
    </plugin>
    <scene>
      <ambient>1 1 1</ambient>
      <background>0.8 0.8 0.8</background>
      <grid>false</grid>
    </scene>
    <gui fullscreen="0">
      <window>
        <width>1000</width>
        <height>845</height>
        <style material_theme="Light" material_primary="DeepOrange" material_accent="LightBlue" toolbar_color_light="#f3f3f3" toolbar_text_color_light="#111111" toolbar_color_dark="#414141" toolbar_text_color_dark="#f3f3f3" plugin_toolbar_color_light="#bbdefb" plugin_toolbar_text_color_light="#111111" plugin_toolbar_color_dark="#607d8b" plugin_toolbar_text_color_dark="#eeeeee" />
        <menus>
          <drawer default="false">
          </drawer>
        </menus>
      </window>
      <plugin filename="MinimalScene" name="3D View">
        <gz-gui>
          <title>3D View</title>
          <property type="bool" key="showTitleBar">false</property>
          <property type="string" key="state">docked</property>
        </gz-gui>
        <engine>ogre2</engine>
        <scene>scene</scene>
        <ambient_light>0.4 0.4 0.4</ambient_light>
        <background_color>0.8 0.8 0.8</background_color>
        <camera_pose>9.292494616150767 -33.39457445660149 10 0 0.6 1.57</camera_pose>
      </plugin>
      <plugin filename="EntityContextMenuPlugin" name="Entity context menu">
        <gz-gui>
          <property key="state" type="string">floating</property>
          <property key="width" type="double">5</property>
          <property key="height" type="double">5</property>
          <property key="showTitleBar" type="bool">false</property>
        </gz-gui>
      </plugin>
      <plugin filename="GzSceneManager" name="Scene Manager">
        <gz-gui>
          <property key="resizable" type="bool">false</property>
          <property key="width" type="double">5</property>
          <property key="height" type="double">5</property>
          <property key="state" type="string">floating</property>
          <property key="showTitleBar" type="bool">false</property>
        </gz-gui>
      </plugin>
      <plugin filename="InteractiveViewControl" name="Interactive view control">
        <gz-gui>
          <property key="resizable" type="bool">false</property>
          <property key="width" type="double">5</property>
          <property key="height" type="double">5</property>
          <property key="state" type="string">floating</property>
          <property key="showTitleBar" type="bool">false</property>
        </gz-gui>
      </plugin>
      <plugin filename="CameraTracking" name="Camera Tracking">
        <gz-gui>
          <property key="resizable" type="bool">false</property>
          <property key="width" type="double">5</property>
          <property key="height" type="double">5</property>
          <property key="state" type="string">floating</property>
          <property key="showTitleBar" type="bool">false</property>
        </gz-gui>
      </plugin>
      <plugin filename="MarkerManager" name="Marker manager">
        <gz-gui>
          <property key="resizable" type="bool">false</property>
          <property key="width" type="double">5</property>
          <property key="height" type="double">5</property>
          <property key="state" type="string">floating</property>
          <property key="showTitleBar" type="bool">false</property>
        </gz-gui>
      </plugin>
      <plugin filename="SelectEntities" name="Select Entities">
        <gz-gui>
          <property key="resizable" type="bool">false</property>
          <property key="width" type="double">5</property>
          <property key="height" type="double">5</property>
          <property key="state" type="string">floating</property>
          <property key="showTitleBar" type="bool">false</property>
        </gz-gui>
      </plugin>
      <plugin filename="Spawn" name="Spawn Entities">
        <gz-gui>
          <property key="resizable" type="bool">false</property>
          <property key="width" type="double">5</property>
          <property key="height" type="double">5</property>
          <property key="state" type="string">floating</property>
          <property key="showTitleBar" type="bool">false</property>
        </gz-gui>
      </plugin>
      <plugin filename="VisualizationCapabilities" name="Visualization Capabilities">
        <gz-gui>
          <property key="resizable" type="bool">false</property>
          <property key="width" type="double">5</property>
          <property key="height" type="double">5</property>
          <property key="state" type="string">floating</property>
          <property key="showTitleBar" type="bool">false</property>
        </gz-gui>
      </plugin>
      <plugin filename="WorldControl" name="World control">
        <gz-gui>
          <title>World control</title>
          <property type="bool" key="showTitleBar">false</property>
          <property type="bool" key="resizable">false</property>
          <property type="double" key="height">72</property>
          <property type="double" key="z">1</property>
          <property type="string" key="state">floating</property>
          <anchors target="3D View">
            <line own="left" target="left" />
            <line own="bottom" target="bottom" />
          </anchors>
        </gz-gui>
        <play_pause>true</play_pause>
        <step>true</step>
        <start_paused>true</start_paused>
        <use_event>true</use_event>
      </plugin>
      <plugin filename="WorldStats" name="World stats">
        <gz-gui>
          <title>World stats</title>
          <property type="bool" key="showTitleBar">false</property>
          <property type="bool" key="resizable">false</property>
          <property type="double" key="height">110</property>
          <property type="double" key="width">290</property>
          <property type="double" key="z">1</property>
          <property type="string" key="state">floating</property>
          <anchors target="3D View">
            <line own="right" target="right" />
            <line own="bottom" target="bottom" />
          </anchors>
        </gz-gui>
        <sim_time>true</sim_time>
        <real_time>true</real_time>
        <real_time_factor>true</real_time_factor>
        <iterations>true</iterations>
      </plugin>
      <plugin filename="Shapes" name="Shapes">
        <gz-gui>
          <property key="resizable" type="bool">false</property>
          <property key="x" type="double">0</property>
          <property key="y" type="double">0</property>
          <property key="width" type="double">250</property>
          <property key="height" type="double">50</property>
          <property key="state" type="string">floating</property>
          <property key="showTitleBar" type="bool">false</property>
          <property key="cardBackground" type="string">#666666</property>
        </gz-gui>
      </plugin>
      <plugin filename="Lights" name="Lights">
        <gz-gui>
          <property key="resizable" type="bool">false</property>
          <property key="x" type="double">250</property>
          <property key="y" type="double">0</property>
          <property key="width" type="double">150</property>
          <property key="height" type="double">50</property>
          <property key="state" type="string">floating</property>
          <property key="showTitleBar" type="bool">false</property>
          <property key="cardBackground" type="string">#666666</property>
        </gz-gui>
      </plugin>
      <plugin filename="TransformControl" name="Transform control">
        <gz-gui>
          <property key="resizable" type="bool">false</property>
          <property key="x" type="double">0</property>
          <property key="y" type="double">50</property>
          <property key="width" type="double">250</property>
          <property key="height" type="double">50</property>
          <property key="state" type="string">floating</property>
          <property key="showTitleBar" type="bool">false</property>
          <property key="cardBackground" type="string">#777777</property>
        </gz-gui>
      </plugin>
      <plugin filename="Screenshot" name="Screenshot">
        <gz-gui>
          <property key="resizable" type="bool">false</property>
          <property key="x" type="double">250</property>
          <property key="y" type="double">50</property>
          <property key="width" type="double">50</property>
          <property key="height" type="double">50</property>
          <property key="state" type="string">floating</property>
          <property key="showTitleBar" type="bool">false</property>
          <property key="cardBackground" type="string">#777777</property>
        </gz-gui>
      </plugin>
      <plugin filename="CopyPaste" name="CopyPaste">
        <gz-gui>
          <property key="resizable" type="bool">false</property>
          <property key="x" type="double">300</property>
          <property key="y" type="double">50</property>
          <property key="width" type="double">100</property>
          <property key="height" type="double">50</property>
          <property key="state" type="string">floating</property>
          <property key="showTitleBar" type="bool">false</property>
          <property key="cardBackground" type="string">#777777</property>
        </gz-gui>
      </plugin>
      <plugin filename="ComponentInspector" name="Component inspector">
        <gz-gui>
          <property type="bool" key="showTitleBar">false</property>
          <property type="string" key="state">docked</property>
        </gz-gui>
      </plugin>
      <plugin filename="EntityTree" name="Entity tree">
        <gz-gui>
          <property type="bool" key="showTitleBar">false</property>
          <property type="string" key="state">docked</property>
        </gz-gui>
      </plugin>
      <plugin filename="toggle_charging" name="toggle_charging" />
      <plugin name="toggle_floors" filename="toggle_floors">
        <floor name="L1" model_name="coworking_L1">
          <model name="null" />
          <model name="null" />
          <model name="null" />
          <model name="null" />
          <model name="null" />
          <model name="null" />
          <model name="null" />
          <model name="null" />
          <model name="null" />
          <model name="null" />
          <model name="null" />
          <model name="null" />
        </floor>
      </plugin>
    </gui>
    <light type="directional" name="sun">
      <cast_shadows>true</cast_shadows>
      <pose>0 0 10 0 0 0</pose>
      <diffuse>1 1 1 1</diffuse>
      <specular>0.2 0.2 0.2 1</specular>
      <attenuation>
        <range>1000</range>
        <constant>0.09</constant>
        <linear>0.001</linear>
        <quadratic>0.001</quadratic>
      </attenuation>
      <direction>-0.5 0.1 -0.9</direction>
    </light>
    <model name="null">
      <pose>12.48811398566685 -4.525056904726784 0.0 0 0 -1.570014642685069</pose>
      <link name="right">
        <pose>0 0 1.11 0 0 0</pose>
        <visual name="right_visual">
          <geometry>
            <box>
              <size>0.7769928112189544 0.03 2.2</size>
            </box>
          </geometry>
          <material>
            <ambient>0.5 0.25 0 0.6</ambient>
            <diffuse>0.5 0.25 0 0.6</diffuse>
            <pbr>
              <metal>
                <metalness>0.0</metalness>
              </metal>
            </pbr>
          </material>
        </visual>
        <collision name="right_collision">
          <geometry>
            <box>
              <size>0.7769928112189544 0.03 2.2</size>
            </box>
          </geometry>
          <surface>
            <contact>
              <collide_bitmask>0x02</collide_bitmask>
            </contact>
          </surface>
        </collision>
        <inertial>
          <mass>50.0</mass>
          <inertia>
            <ixx>20.17041666666667</ixx>
            <iyy>22.682157619524727</iyy>
            <izz>2.519240952858057</izz>
          </inertia>
        </inertial>
      </link>
      <joint name="right_joint" type="revolute">
        <parent>world</parent>
        <child>right</child>
        <axis>
          <xyz>0 0 -1</xyz>
          <limit>
            <lower>0</lower>
            <upper>1.57</upper>
          </limit>
        </axis>
        <pose>0.3934964056094772 0 0 0 0 0</pose>
      </joint>
      <plugin name="register_component" filename="libregister_component.so">
        <component name="Door">
          <v_max_door>0.5</v_max_door>
          <a_max_door>0.3</a_max_door>
          <a_nom_door>0.15</a_nom_door>
          <dx_min_door>0.01</dx_min_door>
          <f_max_door>500.0</f_max_door>
          <ros_interface>true</ros_interface>
          <door name="null" type="SwingDoor" left_joint_name="empty_joint" right_joint_name="right_joint" />
        </component>
      </plugin>
    </model>
    <model name="null">
      <pose>8.32998443808367 -11.225580661847921 0.0 0 0 1.5667836455427138</pose>
      <link name="right">
        <pose>0 0 1.11 0 0 0</pose>
        <visual name="right_visual">
          <geometry>
            <box>
              <size>1.100640723700182 0.03 2.2</size>
            </box>
          </geometry>
          <material>
            <ambient>0.5 0.25 0 0.6</ambient>
            <diffuse>0.5 0.25 0 0.6</diffuse>
            <pbr>
              <metal>
                <metalness>0.0</metalness>
              </metal>
            </pbr>
          </material>
        </visual>
        <collision name="right_collision">
          <geometry>
            <box>
              <size>1.100640723700182 0.03 2.2</size>
            </box>
          </geometry>
          <surface>
            <contact>
              <collide_bitmask>0x02</collide_bitmask>
            </contact>
          </surface>
        </collision>
        <inertial>
          <mass>50.0</mass>
          <inertia>
            <ixx>20.17041666666667</ixx>
            <iyy>25.214208344446924</iyy>
            <izz>5.051291677780252</izz>
          </inertia>
        </inertial>
      </link>
      <joint name="right_joint" type="revolute">
        <parent>world</parent>
        <child>right</child>
        <axis>
          <xyz>0 0 -1</xyz>
          <limit>
            <lower>0</lower>
            <upper>1.57</upper>
          </limit>
        </axis>
        <pose>0.555320361850091 0 0 0 0 0</pose>
      </joint>
      <plugin name="register_component" filename="libregister_component.so">
        <component name="Door">
          <v_max_door>0.5</v_max_door>
          <a_max_door>0.3</a_max_door>
          <a_nom_door>0.15</a_nom_door>
          <dx_min_door>0.01</dx_min_door>
          <f_max_door>500.0</f_max_door>
          <ros_interface>true</ros_interface>
          <door name="null" type="SwingDoor" left_joint_name="empty_joint" right_joint_name="right_joint" />
        </component>
      </plugin>
    </model>
    <model name="null">
      <pose>8.85873140091677 -19.483425025654032 0.0 0 0 -3.1394034632642893</pose>
      <link name="right">
        <pose>0 0 1.11 0 0 0</pose>
        <visual name="right_visual">
          <geometry>
            <box>
              <size>1.026607640762353 0.03 2.2</size>
            </box>
          </geometry>
          <material>
            <ambient>0.5 0.25 0 0.6</ambient>
            <diffuse>0.5 0.25 0 0.6</diffuse>
            <pbr>
              <metal>
                <metalness>0.0</metalness>
              </metal>
            </pbr>
          </material>
        </visual>
        <collision name="right_collision">
          <geometry>
            <box>
              <size>1.026607640762353 0.03 2.2</size>
            </box>
          </geometry>
          <surface>
            <contact>
              <collide_bitmask>0x02</collide_bitmask>
            </contact>
          </surface>
        </collision>
        <inertial>
          <mass>50.0</mass>
          <inertia>
            <ixx>20.17041666666667</ixx>
            <iyy>24.558013533631858</iyy>
            <izz>4.3950968669651855</izz>
          </inertia>
        </inertial>
      </link>
      <joint name="right_joint" type="revolute">
        <parent>world</parent>
        <child>right</child>
        <axis>
          <xyz>0 0 -1</xyz>
          <limit>
            <lower>0</lower>
            <upper>1.57</upper>
          </limit>
        </axis>
        <pose>0.5183038203811765 0 0 0 0 0</pose>
      </joint>
      <plugin name="register_component" filename="libregister_component.so">
        <component name="Door">
          <v_max_door>0.5</v_max_door>
          <a_max_door>0.3</a_max_door>
          <a_nom_door>0.15</a_nom_door>
          <dx_min_door>0.01</dx_min_door>
          <f_max_door>500.0</f_max_door>
          <ros_interface>true</ros_interface>
          <door name="null" type="SwingDoor" left_joint_name="empty_joint" right_joint_name="right_joint" />
        </component>
      </plugin>
    </model>
    <model name="null">
      <pose>8.342096643088393 -18.93821175251824 0.0 0 0 1.567743665190054</pose>
      <link name="right">
        <pose>0 0 1.11 0 0 0</pose>
        <visual name="right_visual">
          <geometry>
            <box>
              <size>1.0827009671731607 0.03 2.2</size>
            </box>
          </geometry>
          <material>
            <ambient>0.5 0.25 0 0.6</ambient>
            <diffuse>0.5 0.25 0 0.6</diffuse>
            <pbr>
              <metal>
                <metalness>0.0</metalness>
              </metal>
            </pbr>
          </material>
        </visual>
        <collision name="right_collision">
          <geometry>
            <box>
              <size>1.0827009671731607 0.03 2.2</size>
            </box>
          </geometry>
          <surface>
            <contact>
              <collide_bitmask>0x02</collide_bitmask>
            </contact>
          </surface>
        </collision>
        <inertial>
          <mass>50.0</mass>
          <inertia>
            <ixx>20.17041666666667</ixx>
            <iyy>25.05100576799041</iyy>
            <izz>4.8880891013237395</izz>
          </inertia>
        </inertial>
      </link>
      <joint name="right_joint" type="revolute">
        <parent>world</parent>
        <child>right</child>
        <axis>
          <xyz>0 0 -1</xyz>
          <limit>
            <lower>0</lower>
            <upper>1.57</upper>
          </limit>
        </axis>
        <pose>0.5463504835865803 0 0 0 0 0</pose>
      </joint>
      <plugin name="register_component" filename="libregister_component.so">
        <component name="Door">
          <v_max_door>0.5</v_max_door>
          <a_max_door>0.3</a_max_door>
          <a_nom_door>0.15</a_nom_door>
          <dx_min_door>0.01</dx_min_door>
          <f_max_door>500.0</f_max_door>
          <ros_interface>true</ros_interface>
          <door name="null" type="SwingDoor" left_joint_name="empty_joint" right_joint_name="right_joint" />
        </component>
      </plugin>
    </model>
    <model name="null">
      <pose>4.942470010270433 -18.908457560427067 0.0 0 0 1.5727212646666853</pose>
      <link name="right">
        <pose>0 0 1.11 0 0 0</pose>
        <visual name="right_visual">
          <geometry>
            <box>
              <size>1.048179419160907 0.03 2.2</size>
            </box>
          </geometry>
          <material>
            <ambient>0.5 0.25 0 0.6</ambient>
            <diffuse>0.5 0.25 0 0.6</diffuse>
            <pbr>
              <metal>
                <metalness>0.0</metalness>
              </metal>
            </pbr>
          </material>
        </visual>
        <collision name="right_collision">
          <geometry>
            <box>
              <size>1.048179419160907 0.03 2.2</size>
            </box>
          </geometry>
          <surface>
            <contact>
              <collide_bitmask>0x02</collide_bitmask>
            </contact>
          </surface>
        </collision>
        <inertial>
          <mass>50.0</mass>
          <inertia>
            <ixx>20.17041666666667</ixx>
            <iyy>24.744500394802074</iyy>
            <izz>4.581583728135403</izz>
          </inertia>
        </inertial>
      </link>
      <joint name="right_joint" type="revolute">
        <parent>world</parent>
        <child>right</child>
        <axis>
          <xyz>0 0 1</xyz>
          <limit>
            <lower>0</lower>
            <upper>1.57</upper>
          </limit>
        </axis>
        <pose>0.5290897095804535 0 0 0 0 0</pose>
      </joint>
      <plugin name="register_component" filename="libregister_component.so">
        <component name="Door">
          <v_max_door>0.5</v_max_door>
          <a_max_door>0.3</a_max_door>
          <a_nom_door>0.15</a_nom_door>
          <dx_min_door>0.01</dx_min_door>
          <f_max_door>500.0</f_max_door>
          <ros_interface>true</ros_interface>
          <door name="null" type="SwingDoor" left_joint_name="empty_joint" right_joint_name="right_joint" />
        </component>
      </plugin>
    </model>
    <model name="null">
      <pose>8.345849239334212 -17.80328037171745 0.0 0 0 -1.57433833430291</pose>
      <link name="right">
        <pose>0 0 1.11 0 0 0</pose>
        <visual name="right_visual">
          <geometry>
            <box>
              <size>1.167174270023015 0.03 2.2</size>
            </box>
          </geometry>
          <material>
            <ambient>0.5 0.25 0 0.6</ambient>
            <diffuse>0.5 0.25 0 0.6</diffuse>
            <pbr>
              <metal>
                <metalness>0.0</metalness>
              </metal>
            </pbr>
          </material>
        </visual>
        <collision name="right_collision">
          <geometry>
            <box>
              <size>1.167174270023015 0.03 2.2</size>
            </box>
          </geometry>
          <surface>
            <contact>
              <collide_bitmask>0x02</collide_bitmask>
            </contact>
          </surface>
        </collision>
        <inertial>
          <mass>50.0</mass>
          <inertia>
            <ixx>20.17041666666667</ixx>
            <iyy>25.84289906918233</iyy>
            <izz>5.679982402515658</izz>
          </inertia>
        </inertial>
      </link>
      <joint name="right_joint" type="revolute">
        <parent>world</parent>
        <child>right</child>
        <axis>
          <xyz>0 0 1</xyz>
          <limit>
            <lower>0</lower>
            <upper>1.57</upper>
          </limit>
        </axis>
        <pose>0.5885871350115075 0 0 0 0 0</pose>
      </joint>
      <plugin name="register_component" filename="libregister_component.so">
        <component name="Door">
          <v_max_door>0.5</v_max_door>
          <a_max_door>0.3</a_max_door>
          <a_nom_door>0.15</a_nom_door>
          <dx_min_door>0.01</dx_min_door>
          <f_max_door>500.0</f_max_door>
          <ros_interface>true</ros_interface>
          <door name="null" type="SwingDoor" left_joint_name="empty_joint" right_joint_name="right_joint" />
        </component>
      </plugin>
    </model>
    <model name="null">
      <pose>11.167165930487677 -22.41072351059881 0.0 0 0 -1.5691788397239672</pose>
      <link name="right">
        <pose>0 0 1.11 0 0 0</pose>
        <visual name="right_visual">
          <geometry>
            <box>
              <size>1.1056367032209087 0.03 2.2</size>
            </box>
          </geometry>
          <material>
            <ambient>0.5 0.25 0 0.6</ambient>
            <diffuse>0.5 0.25 0 0.6</diffuse>
            <pbr>
              <metal>
                <metalness>0.0</metalness>
              </metal>
            </pbr>
          </material>
        </visual>
        <collision name="right_collision">
          <geometry>
            <box>
              <size>1.1056367032209087 0.03 2.2</size>
            </box>
          </geometry>
          <surface>
            <contact>
              <collide_bitmask>0x02</collide_bitmask>
            </contact>
          </surface>
        </collision>
        <inertial>
          <mass>50.0</mass>
          <inertia>
            <ixx>20.17041666666667</ixx>
            <iyy>25.260135497955</iyy>
            <izz>5.097218831288331</izz>
          </inertia>
        </inertial>
      </link>
      <joint name="right_joint" type="revolute">
        <parent>world</parent>
        <child>right</child>
        <axis>
          <xyz>0 0 -1</xyz>
          <limit>
            <lower>0</lower>
            <upper>1.57</upper>
          </limit>
        </axis>
        <pose>0.5578183516104543 0 0 0 0 0</pose>
      </joint>
      <plugin name="register_component" filename="libregister_component.so">
        <component name="Door">
          <v_max_door>0.5</v_max_door>
          <a_max_door>0.3</a_max_door>
          <a_nom_door>0.15</a_nom_door>
          <dx_min_door>0.01</dx_min_door>
          <f_max_door>500.0</f_max_door>
          <ros_interface>true</ros_interface>
          <door name="null" type="SwingDoor" left_joint_name="empty_joint" right_joint_name="right_joint" />
        </component>
      </plugin>
    </model>
    <model name="null">
      <pose>11.745578402104245 -19.475229464818447 0.0 0 0 -3.1405189456970897</pose>
      <link name="right">
        <pose>0 0 1.11 0 0 0</pose>
        <visual name="right_visual">
          <geometry>
            <box>
              <size>1.1486301382521236 0.03 2.2</size>
            </box>
          </geometry>
          <material>
            <ambient>0.5 0.25 0 0.6</ambient>
            <diffuse>0.5 0.25 0 0.6</diffuse>
            <pbr>
              <metal>
                <metalness>0.0</metalness>
              </metal>
            </pbr>
          </material>
        </visual>
        <collision name="right_collision">
          <geometry>
            <box>
              <size>1.1486301382521236 0.03 2.2</size>
            </box>
          </geometry>
          <surface>
            <contact>
              <collide_bitmask>0x02</collide_bitmask>
            </contact>
          </surface>
        </collision>
        <inertial>
          <mass>50.0</mass>
          <inertia>
            <ixx>20.17041666666667</ixx>
            <iyy>25.663963310421224</iyy>
            <izz>5.501046643754552</izz>
          </inertia>
        </inertial>
      </link>
      <joint name="right_joint" type="revolute">
        <parent>world</parent>
        <child>right</child>
        <axis>
          <xyz>0 0 -1</xyz>
          <limit>
            <lower>0</lower>
            <upper>1.57</upper>
          </limit>
        </axis>
        <pose>0.5793150691260618 0 0 0 0 0</pose>
      </joint>
      <plugin name="register_component" filename="libregister_component.so">
        <component name="Door">
          <v_max_door>0.5</v_max_door>
          <a_max_door>0.3</a_max_door>
          <a_nom_door>0.15</a_nom_door>
          <dx_min_door>0.01</dx_min_door>
          <f_max_door>500.0</f_max_door>
          <ros_interface>true</ros_interface>
          <door name="null" type="SwingDoor" left_joint_name="empty_joint" right_joint_name="right_joint" />
        </component>
      </plugin>
    </model>
    <model name="null">
      <pose>12.531320107469812 -8.33521346563932 0.0 0 0 1.5707963267948966</pose>
      <link name="right">
        <pose>0 0 1.11 0 0 0</pose>
        <visual name="right_visual">
          <geometry>
            <box>
              <size>1.0232421743362037 0.03 2.2</size>
            </box>
          </geometry>
          <material>
            <ambient>0.5 0.25 0 0.6</ambient>
            <diffuse>0.5 0.25 0 0.6</diffuse>
            <pbr>
              <metal>
                <metalness>0.0</metalness>
              </metal>
            </pbr>
          </material>
        </visual>
        <collision name="right_collision">
          <geometry>
            <box>
              <size>1.0232421743362037 0.03 2.2</size>
            </box>
          </geometry>
          <surface>
            <contact>
              <collide_bitmask>0x02</collide_bitmask>
            </contact>
          </surface>
        </collision>
        <inertial>
          <mass>50.0</mass>
          <inertia>
            <ixx>20.17041666666667</ixx>
            <iyy>24.52926894725118</iyy>
            <izz>4.366352280584508</izz>
          </inertia>
        </inertial>
      </link>
      <joint name="right_joint" type="revolute">
        <parent>world</parent>
        <child>right</child>
        <axis>
          <xyz>0 0 1</xyz>
          <limit>
            <lower>0</lower>
            <upper>1.57</upper>
          </limit>
        </axis>
        <pose>0.5166210871681018 0 0 0 0 0</pose>
      </joint>
      <plugin name="register_component" filename="libregister_component.so">
        <component name="Door">
          <v_max_door>0.5</v_max_door>
          <a_max_door>0.3</a_max_door>
          <a_nom_door>0.15</a_nom_door>
          <dx_min_door>0.01</dx_min_door>
          <f_max_door>500.0</f_max_door>
          <ros_interface>true</ros_interface>
          <door name="null" type="SwingDoor" left_joint_name="empty_joint" right_joint_name="right_joint" />
        </component>
      </plugin>
    </model>
    <model name="null">
      <pose>8.333853234941838 -10.225134401514342 0.0 0 0 -1.5744817006077487</pose>
      <link name="right">
        <pose>0 0 1.11 0 0 0</pose>
        <visual name="right_visual">
          <geometry>
            <box>
              <size>0.8802667842933769 0.03 2.2</size>
            </box>
          </geometry>
          <material>
            <ambient>0.5 0.25 0 0.6</ambient>
            <diffuse>0.5 0.25 0 0.6</diffuse>
            <pbr>
              <metal>
                <metalness>0.0</metalness>
              </metal>
            </pbr>
          </material>
        </visual>
        <collision name="right_collision">
          <geometry>
            <box>
              <size>0.8802667842933769 0.03 2.2</size>
            </box>
          </geometry>
          <surface>
            <contact>
              <collide_bitmask>0x02</collide_bitmask>
            </contact>
          </surface>
        </collision>
        <inertial>
          <mass>50.0</mass>
          <inertia>
            <ixx>20.17041666666667</ixx>
            <iyy>23.395290048042515</iyy>
            <izz>3.232373381375844</izz>
          </inertia>
        </inertial>
      </link>
      <joint name="right_joint" type="revolute">
        <parent>world</parent>
        <child>right</child>
        <axis>
          <xyz>0 0 1</xyz>
          <limit>
            <lower>0</lower>
            <upper>1.57</upper>
          </limit>
        </axis>
        <pose>0.44513339214668846 0 0 0 0 0</pose>
      </joint>
      <plugin name="register_component" filename="libregister_component.so">
        <component name="Door">
          <v_max_door>0.5</v_max_door>
          <a_max_door>0.3</a_max_door>
          <a_nom_door>0.15</a_nom_door>
          <dx_min_door>0.01</dx_min_door>
          <f_max_door>500.0</f_max_door>
          <ros_interface>true</ros_interface>
          <door name="null" type="SwingDoor" left_joint_name="empty_joint" right_joint_name="right_joint" />
        </component>
      </plugin>
    </model>
    <model name="null">
      <pose>5.197646554986163 -7.683512584281992 0.0 0 0 1.5811935104813961</pose>
      <link name="right">
        <pose>0.4322623004888328 0 1.11 0 0 0</pose>
        <visual name="right_visual">
          <geometry>
            <box>
              <size>0.8545246009776656 0.03 2.2</size>
            </box>
          </geometry>
          <material>
            <ambient>0.5 0.25 0 0.6</ambient>
            <diffuse>0.5 0.25 0 0.6</diffuse>
            <pbr>
              <metal>
                <metalness>0.0</metalness>
              </metal>
            </pbr>
          </material>
        </visual>
        <collision name="right_collision">
          <geometry>
            <box>
              <size>0.8545246009776656 0.03 2.2</size>
            </box>
          </geometry>
          <surface>
            <contact>
              <collide_bitmask>0x02</collide_bitmask>
            </contact>
          </surface>
        </collision>
        <inertial>
          <mass>50.0</mass>
          <inertia>
            <ixx>20.17041666666667</ixx>
            <iyy>23.209217890316832</iyy>
            <izz>3.0463012236501608</izz>
          </inertia>
        </inertial>
      </link>
      <joint name="right_joint" type="prismatic">
        <parent>world</parent>
        <child>right</child>
        <axis>
          <xyz>1 0 0</xyz>
          <limit>
            <lower>0.0</lower>
            <upper>0.8645246009776656</upper>
            <effort>500.0</effort>
          </limit>
        </axis>
      </joint>
      <link name="left">
        <pose>-0.4322623004888328 0 1.11 0 0 0</pose>
        <visual name="left_visual">
          <geometry>
            <box>
              <size>0.8545246009776656 0.03 2.2</size>
            </box>
          </geometry>
          <material>
            <ambient>0.5 0.25 0 0.6</ambient>
            <diffuse>0.5 0.25 0 0.6</diffuse>
            <pbr>
              <metal>
                <metalness>0.0</metalness>
              </metal>
            </pbr>
          </material>
        </visual>
        <collision name="left_collision">
          <geometry>
            <box>
              <size>0.8545246009776656 0.03 2.2</size>
            </box>
          </geometry>
          <surface>
            <contact>
              <collide_bitmask>0x02</collide_bitmask>
            </contact>
          </surface>
        </collision>
        <inertial>
          <mass>50.0</mass>
          <inertia>
            <ixx>20.17041666666667</ixx>
            <iyy>23.209217890316832</iyy>
            <izz>3.0463012236501608</izz>
          </inertia>
        </inertial>
      </link>
      <joint name="left_joint" type="prismatic">
        <parent>world</parent>
        <child>left</child>
        <axis>
          <xyz>1 0 0</xyz>
          <limit>
            <lower>-0.8645246009776656</lower>
            <upper>0.0</upper>
            <effort>500.0</effort>
          </limit>
        </axis>
      </joint>
      <plugin name="register_component" filename="libregister_component.so">
        <component name="Door">
          <v_max_door>0.2</v_max_door>
          <a_max_door>0.2</a_max_door>
          <a_nom_door>0.08</a_nom_door>
          <dx_min_door>0.001</dx_min_door>
          <f_max_door>100.0</f_max_door>
          <ros_interface>true</ros_interface>
          <door name="null" type="DoubleSlidingDoor" left_joint_name="left_joint" right_joint_name="right_joint" />
        </component>
      </plugin>
    </model>
    <model name="null">
      <pose>4.975231747622368 -11.884321933247499 0.0 0 0 1.5601283736830944</pose>
      <link name="right">
        <pose>0.4850455383707938 0 1.11 0 0 0</pose>
        <visual name="right_visual">
          <geometry>
            <box>
              <size>0.9600910767415876 0.03 2.2</size>
            </box>
          </geometry>
          <material>
            <ambient>0.5 0.25 0 0.6</ambient>
            <diffuse>0.5 0.25 0 0.6</diffuse>
            <pbr>
              <metal>
                <metalness>0.0</metalness>
              </metal>
            </pbr>
          </material>
        </visual>
        <collision name="right_collision">
          <geometry>
            <box>
              <size>0.9600910767415876 0.03 2.2</size>
            </box>
          </geometry>
          <surface>
            <contact>
              <collide_bitmask>0x02</collide_bitmask>
            </contact>
          </surface>
        </collision>
        <inertial>
          <mass>50.0</mass>
          <inertia>
            <ixx>20.17041666666667</ixx>
            <iyy>24.00739531516176</iyy>
            <izz>3.844478648495088</izz>
          </inertia>
        </inertial>
      </link>
      <joint name="right_joint" type="prismatic">
        <parent>world</parent>
        <child>right</child>
        <axis>
          <xyz>1 0 0</xyz>
          <limit>
            <lower>0.0</lower>
            <upper>0.9700910767415876</upper>
            <effort>500.0</effort>
          </limit>
        </axis>
      </joint>
      <link name="left">
        <pose>-0.4850455383707938 0 1.11 0 0 0</pose>
        <visual name="left_visual">
          <geometry>
            <box>
              <size>0.9600910767415876 0.03 2.2</size>
            </box>
          </geometry>
          <material>
            <ambient>0.5 0.25 0 0.6</ambient>
            <diffuse>0.5 0.25 0 0.6</diffuse>
            <pbr>
              <metal>
                <metalness>0.0</metalness>
              </metal>
            </pbr>
          </material>
        </visual>
        <collision name="left_collision">
          <geometry>
            <box>
              <size>0.9600910767415876 0.03 2.2</size>
            </box>
          </geometry>
          <surface>
            <contact>
              <collide_bitmask>0x02</collide_bitmask>
            </contact>
          </surface>
        </collision>
        <inertial>
          <mass>50.0</mass>
          <inertia>
            <ixx>20.17041666666667</ixx>
            <iyy>24.00739531516176</iyy>
            <izz>3.844478648495088</izz>
          </inertia>
        </inertial>
      </link>
      <joint name="left_joint" type="prismatic">
        <parent>world</parent>
        <child>left</child>
        <axis>
          <xyz>1 0 0</xyz>
          <limit>
            <lower>-0.9700910767415876</lower>
            <upper>0.0</upper>
            <effort>500.0</effort>
          </limit>
        </axis>
      </joint>
      <plugin name="register_component" filename="libregister_component.so">
        <component name="Door">
          <v_max_door>0.2</v_max_door>
          <a_max_door>0.2</a_max_door>
          <a_nom_door>0.08</a_nom_door>
          <dx_min_door>0.001</dx_min_door>
          <f_max_door>100.0</f_max_door>
          <ros_interface>true</ros_interface>
          <door name="null" type="DoubleSlidingDoor" left_joint_name="left_joint" right_joint_name="right_joint" />
        </component>
      </plugin>
    </model>
    <include>
      <name>coworking_L1</name>
      <uri>model://coworking_L1</uri>
      <pose>0 0 0.0 0 0 0</pose>
    </include>
    <rmf_charger_waypoints name="charger_waypoints" />
  </world>
</sdf>
